
device: cuda:0
padded_paths:[[(5, 9), (18, 2)], [(5, 10), (17, 2)], [(6, 10), (17, 3)], [(7, 10), (17, 4)], [(8, 10), (17, 5)], [(9, 10), (17, 6)], [(10, 10), (16, 6)], [(10, 9), (16, 7)], [(11, 9), (16, 8)], [(11, 9), (15, 8)], [(11, 9), (15, 9)], [(11, 9), (14, 9)], [(11, 9), (13, 9)], [(11, 9), (12, 9)], [(11, 9), (12, 10)], [(11, 9), (11, 10)], [(11, 9), (10, 10)], [(11, 9), (9, 10)], [(11, 9), (8, 10)], [(11, 9), (7, 10)], [(11, 9), (6, 10)], [(11, 9), (5, 10)], [(11, 9), (4, 10)], [(11, 9), (3, 10)], [(11, 9), (2, 10)]]
Exception in thread MsgRouterThr:
Traceback (most recent call last):
  File "/home/bld/anaconda3/envs/raylib/lib/python3.8/threading.py", line 932, in _bootstrap_inner
    self.run()
  File "/home/bld/anaconda3/envs/raylib/lib/python3.8/threading.py", line 870, in run
    self._target(*self._args, **self._kwargs)
  File "/home/bld/anaconda3/envs/raylib/lib/python3.8/site-packages/wandb/sdk/interface/router.py", line 70, in message_loop
    msg = self._read_message()
  File "/home/bld/anaconda3/envs/raylib/lib/python3.8/site-packages/wandb/sdk/interface/router_sock.py", line 27, in _read_message
    resp = self._sock_client.read_server_response(timeout=1)
  File "/home/bld/anaconda3/envs/raylib/lib/python3.8/site-packages/wandb/sdk/lib/sock_client.py", line 285, in read_server_response
    data = self._read_packet_bytes(timeout=timeout)
  File "/home/bld/anaconda3/envs/raylib/lib/python3.8/site-packages/wandb/sdk/lib/sock_client.py", line 255, in _read_packet_bytes
    data = self._sock.recv(self._bufsize)
  File "/home/bld/.vscode-server/extensions/ms-python.debugpy-2024.4.0-linux-x64/bundled/libs/debugpy/_vendored/pydevd/_pydevd_bundle/pydevd_trace_dispatch_regular.py", line 203, in trace_dispatch
    py_db.enable_tracing(thread_trace_func)
  File "/home/bld/.vscode-server/extensions/ms-python.debugpy-2024.4.0-linux-x64/bundled/libs/debugpy/_vendored/pydevd/pydevd.py", line 1107, in enable_tracing
    pydevd_tracing.SetTrace(thread_trace_func)
  File "/home/bld/.vscode-server/extensions/ms-python.debugpy-2024.4.0-linux-x64/bundled/libs/debugpy/_vendored/pydevd/pydevd_tracing.py", line 87, in SetTrace
    if set_trace_to_threads(tracing_func, thread_idents=[thread.get_ident()], create_dummy_thread=False) == 0:
  File "/home/bld/.vscode-server/extensions/ms-python.debugpy-2024.4.0-linux-x64/bundled/libs/debugpy/_vendored/pydevd/pydevd_tracing.py", line 354, in set_trace_to_threads
    start_new_thread(increase_tracing_count, ())
RuntimeError: can't start new thread
Exception in thread ChkStopThr:
Traceback (most recent call last):
  File "/home/bld/anaconda3/envs/raylib/lib/python3.8/threading.py", line 932, in _bootstrap_inner
    self.run()
  File "/home/bld/anaconda3/envs/raylib/lib/python3.8/threading.py", line 870, in run
    self._target(*self._args, **self._kwargs)
  File "/home/bld/anaconda3/envs/raylib/lib/python3.8/site-packages/wandb/sdk/wandb_run.py", line 286, in check_stop_status
