device: cpu
padded_paths:[[(0, 0), (2, 1)], [(1, 0), (3, 1)], [(1, 1), (3, 2)], [(1, 2), (3, 2)], [(1, 3), (3, 2)]],max_length:5
Traceback (most recent call last):
  File "/home/bld/anaconda3/envs/raylib2/lib/python3.8/runpy.py", line 194, in _run_module_as_main
    return _run_code(code, main_globals, None,
  File "/home/bld/anaconda3/envs/raylib2/lib/python3.8/runpy.py", line 87, in _run_code
    exec(code, run_globals)
  File "/home/bld/.vscode-server/extensions/ms-python.debugpy-2024.4.0-linux-x64/bundled/libs/debugpy/_vendored/pydevd/_pydevd_bundle/pydevd_trace_dispatch_regular.py", line 203, in trace_dispatch
  File "/home/bld/.vscode-server/extensions/ms-python.debugpy-2024.4.0-linux-x64/bundled/libs/debugpy/_vendored/pydevd/pydevd.py", line 1107, in enable_tracing
  File "/home/bld/.vscode-server/extensions/ms-python.debugpy-2024.4.0-linux-x64/bundled/libs/debugpy/_vendored/pydevd/pydevd_tracing.py", line 87, in SetTrace
  File "/home/bld/.vscode-server/extensions/ms-python.debugpy-2024.4.0-linux-x64/bundled/libs/debugpy/_vendored/pydevd/pydevd_tracing.py", line 354, in set_trace_to_threads
RuntimeError: can't start new thread
Traceback (most recent call last):
  File "/home/bld/anaconda3/envs/raylib2/lib/python3.8/runpy.py", line 194, in _run_module_as_main
  File "/home/bld/anaconda3/envs/raylib2/lib/python3.8/runpy.py", line 87, in _run_code
  File "/home/bld/.vscode-server/extensions/ms-python.debugpy-2024.4.0-linux-x64/bundled/libs/debugpy/_vendored/pydevd/_pydevd_bundle/pydevd_trace_dispatch_regular.py", line 203, in trace_dispatch
  File "/home/bld/.vscode-server/extensions/ms-python.debugpy-2024.4.0-linux-x64/bundled/libs/debugpy/_vendored/pydevd/pydevd.py", line 1107, in enable_tracing
  File "/home/bld/.vscode-server/extensions/ms-python.debugpy-2024.4.0-linux-x64/bundled/libs/debugpy/_vendored/pydevd/pydevd_tracing.py", line 87, in SetTrace
  File "/home/bld/.vscode-server/extensions/ms-python.debugpy-2024.4.0-linux-x64/bundled/libs/debugpy/_vendored/pydevd/pydevd_tracing.py", line 354, in set_trace_to_threads
RuntimeError: can't start new thread