
device: cuda:0
padded_paths:[[(0, 1), (0, 3)], [(0, 0), (1, 3)], [(0, 0), (2, 3)], [(0, 0), (3, 3)], [(0, 0), (4, 3)], [(0, 0), (4, 2)], [(0, 0), (4, 1)], [(0, 0), (4, 0)]],max_length:8
Epoch 0: Actor Loss = 1.8264589309692383
padded_paths:[[(2, 0), (3, 1)], [(2, 1), (4, 1)], [(2, 2), (4, 2)], [(2, 3), (4, 3)], [(2, 4), (4, 3)]],max_length:5
padded_paths:[[(4, 3), (1, 0)], [(3, 3), (2, 0)], [(2, 3), (3, 0)], [(1, 3), (4, 0)], [(0, 3), (4, 1)], [(0, 4), (4, 1)]],max_length:6
Invalid action, breaking
Invalid action, breaking
Invalid action, breaking
Invalid action, breaking
Traceback (most recent call last):
  File "/home/bld/anaconda3/envs/raylib/lib/python3.8/runpy.py", line 194, in _run_module_as_main
    return _run_code(code, main_globals, None,
  File "/home/bld/anaconda3/envs/raylib/lib/python3.8/runpy.py", line 87, in _run_code
    exec(code, run_globals)
  File "/home/bld/.vscode-server/extensions/ms-python.debugpy-2024.4.0-linux-x64/bundled/libs/debugpy/adapter/../../debugpy/launcher/../../debugpy/__main__.py", line 39, in <module>
    cli.main()
  File "/home/bld/.vscode-server/extensions/ms-python.debugpy-2024.4.0-linux-x64/bundled/libs/debugpy/adapter/../../debugpy/launcher/../../debugpy/../debugpy/server/cli.py", line 430, in main
    run()
  File "/home/bld/.vscode-server/extensions/ms-python.debugpy-2024.4.0-linux-x64/bundled/libs/debugpy/adapter/../../debugpy/launcher/../../debugpy/../debugpy/server/cli.py", line 284, in run_file
    runpy.run_path(target, run_name="__main__")
  File "/home/bld/.vscode-server/extensions/ms-python.debugpy-2024.4.0-linux-x64/bundled/libs/debugpy/_vendored/pydevd/_pydevd_bundle/pydevd_runpy.py", line 321, in run_path
    return _run_module_code(code, init_globals, run_name,
  File "/home/bld/.vscode-server/extensions/ms-python.debugpy-2024.4.0-linux-x64/bundled/libs/debugpy/_vendored/pydevd/_pydevd_bundle/pydevd_runpy.py", line 135, in _run_module_code
    _run_code(code, mod_globals, init_globals,
  File "/home/bld/.vscode-server/extensions/ms-python.debugpy-2024.4.0-linux-x64/bundled/libs/debugpy/_vendored/pydevd/_pydevd_bundle/pydevd_runpy.py", line 124, in _run_code
    exec(code, run_globals)
  File "/home/bld/HK_RL/RLagents_v3/scripts_0.py", line 147, in <module>
    train_a2c(env, actor_net, critic_net)
  File "/home/bld/.vscode-server/extensions/ms-python.debugpy-2024.4.0-linux-x64/bundled/libs/debugpy/_vendored/pydevd/_pydevd_bundle/pydevd_trace_dispatch_regular.py", line 203, in trace_dispatch
    py_db.enable_tracing(thread_trace_func)
  File "/home/bld/.vscode-server/extensions/ms-python.debugpy-2024.4.0-linux-x64/bundled/libs/debugpy/_vendored/pydevd/pydevd.py", line 1107, in enable_tracing
    pydevd_tracing.SetTrace(thread_trace_func)
  File "/home/bld/.vscode-server/extensions/ms-python.debugpy-2024.4.0-linux-x64/bundled/libs/debugpy/_vendored/pydevd/pydevd_tracing.py", line 87, in SetTrace
    if set_trace_to_threads(tracing_func, thread_idents=[thread.get_ident()], create_dummy_thread=False) == 0:
  File "/home/bld/.vscode-server/extensions/ms-python.debugpy-2024.4.0-linux-x64/bundled/libs/debugpy/_vendored/pydevd/pydevd_tracing.py", line 354, in set_trace_to_threads
    start_new_thread(increase_tracing_count, ())
RuntimeError: can't start new thread
Traceback (most recent call last):
  File "/home/bld/anaconda3/envs/raylib/lib/python3.8/runpy.py", line 194, in _run_module_as_main
    return _run_code(code, main_globals, None,
  File "/home/bld/anaconda3/envs/raylib/lib/python3.8/runpy.py", line 87, in _run_code
    exec(code, run_globals)
  File "/home/bld/.vscode-server/extensions/ms-python.debugpy-2024.4.0-linux-x64/bundled/libs/debugpy/adapter/../../debugpy/launcher/../../debugpy/__main__.py", line 39, in <module>
    cli.main()
  File "/home/bld/.vscode-server/extensions/ms-python.debugpy-2024.4.0-linux-x64/bundled/libs/debugpy/adapter/../../debugpy/launcher/../../debugpy/../debugpy/server/cli.py", line 430, in main
    run()
  File "/home/bld/.vscode-server/extensions/ms-python.debugpy-2024.4.0-linux-x64/bundled/libs/debugpy/adapter/../../debugpy/launcher/../../debugpy/../debugpy/server/cli.py", line 284, in run_file
    runpy.run_path(target, run_name="__main__")
  File "/home/bld/.vscode-server/extensions/ms-python.debugpy-2024.4.0-linux-x64/bundled/libs/debugpy/_vendored/pydevd/_pydevd_bundle/pydevd_runpy.py", line 321, in run_path
    return _run_module_code(code, init_globals, run_name,
  File "/home/bld/.vscode-server/extensions/ms-python.debugpy-2024.4.0-linux-x64/bundled/libs/debugpy/_vendored/pydevd/_pydevd_bundle/pydevd_runpy.py", line 135, in _run_module_code
    _run_code(code, mod_globals, init_globals,
  File "/home/bld/.vscode-server/extensions/ms-python.debugpy-2024.4.0-linux-x64/bundled/libs/debugpy/_vendored/pydevd/_pydevd_bundle/pydevd_runpy.py", line 124, in _run_code
    exec(code, run_globals)
  File "/home/bld/HK_RL/RLagents_v3/scripts_0.py", line 147, in <module>
    train_a2c(env, actor_net, critic_net)
  File "/home/bld/.vscode-server/extensions/ms-python.debugpy-2024.4.0-linux-x64/bundled/libs/debugpy/_vendored/pydevd/_pydevd_bundle/pydevd_trace_dispatch_regular.py", line 203, in trace_dispatch
    py_db.enable_tracing(thread_trace_func)
  File "/home/bld/.vscode-server/extensions/ms-python.debugpy-2024.4.0-linux-x64/bundled/libs/debugpy/_vendored/pydevd/pydevd.py", line 1107, in enable_tracing
    pydevd_tracing.SetTrace(thread_trace_func)
  File "/home/bld/.vscode-server/extensions/ms-python.debugpy-2024.4.0-linux-x64/bundled/libs/debugpy/_vendored/pydevd/pydevd_tracing.py", line 87, in SetTrace
    if set_trace_to_threads(tracing_func, thread_idents=[thread.get_ident()], create_dummy_thread=False) == 0:
  File "/home/bld/.vscode-server/extensions/ms-python.debugpy-2024.4.0-linux-x64/bundled/libs/debugpy/_vendored/pydevd/pydevd_tracing.py", line 354, in set_trace_to_threads
    start_new_thread(increase_tracing_count, ())
RuntimeError: can't start new thread