
device: cuda:0
Epoch 0: Actor Loss = 4.875308513641357
blocking paths
Invalid action, breaking
Invalid action, breaking
Invalid action, breaking
Traceback (most recent call last):
  File "/home/bld/anaconda3/envs/raylib/lib/python3.8/runpy.py", line 194, in _run_module_as_main
    return _run_code(code, main_globals, None,
  File "/home/bld/anaconda3/envs/raylib/lib/python3.8/runpy.py", line 87, in _run_code
    exec(code, run_globals)
  File "/home/bld/.vscode-server/extensions/ms-python.debugpy-2024.4.0-linux-x64/bundled/libs/debugpy/_vendored/pydevd/_pydevd_bundle/pydevd_trace_dispatch_regular.py", line 203, in trace_dispatch
    py_db.enable_tracing(thread_trace_func)
  File "/home/bld/.vscode-server/extensions/ms-python.debugpy-2024.4.0-linux-x64/bundled/libs/debugpy/_vendored/pydevd/pydevd.py", line 1107, in enable_tracing
    pydevd_tracing.SetTrace(thread_trace_func)
  File "/home/bld/.vscode-server/extensions/ms-python.debugpy-2024.4.0-linux-x64/bundled/libs/debugpy/_vendored/pydevd/pydevd_tracing.py", line 87, in SetTrace
    if set_trace_to_threads(tracing_func, thread_idents=[thread.get_ident()], create_dummy_thread=False) == 0:
  File "/home/bld/.vscode-server/extensions/ms-python.debugpy-2024.4.0-linux-x64/bundled/libs/debugpy/_vendored/pydevd/pydevd_tracing.py", line 354, in set_trace_to_threads
    start_new_thread(increase_tracing_count, ())
RuntimeError: can't start new thread
Traceback (most recent call last):
  File "/home/bld/anaconda3/envs/raylib/lib/python3.8/runpy.py", line 194, in _run_module_as_main
    return _run_code(code, main_globals, None,
  File "/home/bld/anaconda3/envs/raylib/lib/python3.8/runpy.py", line 87, in _run_code
    exec(code, run_globals)
  File "/home/bld/.vscode-server/extensions/ms-python.debugpy-2024.4.0-linux-x64/bundled/libs/debugpy/_vendored/pydevd/_pydevd_bundle/pydevd_trace_dispatch_regular.py", line 203, in trace_dispatch
    py_db.enable_tracing(thread_trace_func)
  File "/home/bld/.vscode-server/extensions/ms-python.debugpy-2024.4.0-linux-x64/bundled/libs/debugpy/_vendored/pydevd/pydevd.py", line 1107, in enable_tracing
    pydevd_tracing.SetTrace(thread_trace_func)
  File "/home/bld/.vscode-server/extensions/ms-python.debugpy-2024.4.0-linux-x64/bundled/libs/debugpy/_vendored/pydevd/pydevd_tracing.py", line 87, in SetTrace
    if set_trace_to_threads(tracing_func, thread_idents=[thread.get_ident()], create_dummy_thread=False) == 0:
  File "/home/bld/.vscode-server/extensions/ms-python.debugpy-2024.4.0-linux-x64/bundled/libs/debugpy/_vendored/pydevd/pydevd_tracing.py", line 354, in set_trace_to_threads
    start_new_thread(increase_tracing_count, ())
RuntimeError: can't start new thread